<?xml version="1.0" encoding="UTF-8"?>
<testng-results retried="5" ignored="5" total="11" passed="0" failed="1" skipped="0">
  <reporter-output>
  </reporter-output>
  <suite started-at="2023-10-29T14:16:09 EDT" name="Default suite" finished-at="2023-10-29T14:16:51 EDT" duration-ms="41808">
    <groups>
    </groups>
    <test started-at="2023-10-29T14:16:09 EDT" name="Default test" finished-at="2023-10-29T14:16:51 EDT" duration-ms="41808">
      <class name="com.TestNG.Oct_29_Day18_Retry_Failed_TestCases.LoginTest">
        <test-method retried="true" signature="loginValidationCorrectCredentials()[pri:0, instance:com.TestNG.Oct_29_Day18_Retry_Failed_TestCases.LoginTest@5a45133e]" started-at="2023-10-29T14:16:09 EDT" name="loginValidationCorrectCredentials" finished-at="2023-10-29T14:16:17 EDT" duration-ms="8010" status="SKIP">
          <exception class="java.lang.AssertionError">
            <message>
              <![CDATA[Deliberately failing to show students how to retry failed test cases in TestNG]]>
            </message>
            <full-stacktrace>
              <![CDATA[java.lang.AssertionError: Deliberately failing to show students how to retry failed test cases in TestNG
at org.testng.Assert.fail(Assert.java:111)
at com.TestNG.Oct_29_Day18_Retry_Failed_TestCases.LoginTest.loginValidationCorrectCredentials(LoginTest.java:26)
at java.base/jdk.internal.reflect.NativeMethodAccessorImpl.invoke0(Native Method)
at java.base/jdk.internal.reflect.NativeMethodAccessorImpl.invoke(NativeMethodAccessorImpl.java:77)
at java.base/jdk.internal.reflect.DelegatingMethodAccessorImpl.invoke(DelegatingMethodAccessorImpl.java:43)
at java.base/java.lang.reflect.Method.invoke(Method.java:568)
at org.testng.internal.invokers.MethodInvocationHelper.invokeMethod(MethodInvocationHelper.java:139)
at org.testng.internal.invokers.TestInvoker.invokeMethod(TestInvoker.java:664)
at org.testng.internal.invokers.TestInvoker.invokeTestMethod(TestInvoker.java:227)
at org.testng.internal.invokers.MethodRunner.runInSequence(MethodRunner.java:50)
at org.testng.internal.invokers.TestInvoker$MethodInvocationAgent.invoke(TestInvoker.java:957)
at org.testng.internal.invokers.TestInvoker.invokeTestMethods(TestInvoker.java:200)
at org.testng.internal.invokers.TestMethodWorker.invokeTestMethods(TestMethodWorker.java:148)
at org.testng.internal.invokers.TestMethodWorker.run(TestMethodWorker.java:128)
at java.base/java.util.ArrayList.forEach(ArrayList.java:1511)
at org.testng.TestRunner.privateRun(TestRunner.java:848)
at org.testng.TestRunner.run(TestRunner.java:621)
at org.testng.SuiteRunner.runTest(SuiteRunner.java:443)
at org.testng.SuiteRunner.runSequentially(SuiteRunner.java:437)
at org.testng.SuiteRunner.privateRun(SuiteRunner.java:397)
at org.testng.SuiteRunner.run(SuiteRunner.java:336)
at org.testng.SuiteRunnerWorker.runSuite(SuiteRunnerWorker.java:52)
at org.testng.SuiteRunnerWorker.run(SuiteRunnerWorker.java:95)
at org.testng.TestNG.runSuitesSequentially(TestNG.java:1280)
at org.testng.TestNG.runSuitesLocally(TestNG.java:1200)
at org.testng.TestNG.runSuites(TestNG.java:1114)
at org.testng.TestNG.run(TestNG.java:1082)
at org.testng.remote.AbstractRemoteTestNG.run(AbstractRemoteTestNG.java:115)
at org.testng.remote.RemoteTestNG.initAndRun(RemoteTestNG.java:251)
at org.testng.remote.RemoteTestNG.main(RemoteTestNG.java:77)
]]>
            </full-stacktrace>
          </exception> <!-- java.lang.AssertionError -->
          <reporter-output>
          </reporter-output>
        </test-method> <!-- loginValidationCorrectCredentials -->
        <test-method is-config="true" signature="tearDown()[pri:0, instance:com.TestNG.Oct_29_Day18_Retry_Failed_TestCases.LoginTest@5a45133e]" started-at="2023-10-29T14:16:17 EDT" name="tearDown" finished-at="2023-10-29T14:16:18 EDT" duration-ms="181" status="PASS">
          <reporter-output>
          </reporter-output>
        </test-method> <!-- tearDown -->
        <test-method retried="true" signature="loginValidationCorrectCredentials()[pri:0, instance:com.TestNG.Oct_29_Day18_Retry_Failed_TestCases.LoginTest@5a45133e]" started-at="2023-10-29T14:16:18 EDT" name="loginValidationCorrectCredentials" finished-at="2023-10-29T14:16:24 EDT" duration-ms="6716" status="SKIP">
          <exception class="java.lang.AssertionError">
            <message>
              <![CDATA[Deliberately failing to show students how to retry failed test cases in TestNG]]>
            </message>
            <full-stacktrace>
              <![CDATA[java.lang.AssertionError: Deliberately failing to show students how to retry failed test cases in TestNG
at org.testng.Assert.fail(Assert.java:111)
at com.TestNG.Oct_29_Day18_Retry_Failed_TestCases.LoginTest.loginValidationCorrectCredentials(LoginTest.java:26)
at java.base/jdk.internal.reflect.NativeMethodAccessorImpl.invoke0(Native Method)
at java.base/jdk.internal.reflect.NativeMethodAccessorImpl.invoke(NativeMethodAccessorImpl.java:77)
at java.base/jdk.internal.reflect.DelegatingMethodAccessorImpl.invoke(DelegatingMethodAccessorImpl.java:43)
at java.base/java.lang.reflect.Method.invoke(Method.java:568)
at org.testng.internal.invokers.MethodInvocationHelper.invokeMethod(MethodInvocationHelper.java:139)
at org.testng.internal.invokers.TestInvoker.invokeMethod(TestInvoker.java:664)
at org.testng.internal.invokers.TestInvoker.retryFailed(TestInvoker.java:248)
at org.testng.internal.invokers.MethodRunner.runInSequence(MethodRunner.java:62)
at org.testng.internal.invokers.TestInvoker$MethodInvocationAgent.invoke(TestInvoker.java:957)
at org.testng.internal.invokers.TestInvoker.invokeTestMethods(TestInvoker.java:200)
at org.testng.internal.invokers.TestMethodWorker.invokeTestMethods(TestMethodWorker.java:148)
at org.testng.internal.invokers.TestMethodWorker.run(TestMethodWorker.java:128)
at java.base/java.util.ArrayList.forEach(ArrayList.java:1511)
at org.testng.TestRunner.privateRun(TestRunner.java:848)
at org.testng.TestRunner.run(TestRunner.java:621)
at org.testng.SuiteRunner.runTest(SuiteRunner.java:443)
at org.testng.SuiteRunner.runSequentially(SuiteRunner.java:437)
at org.testng.SuiteRunner.privateRun(SuiteRunner.java:397)
at org.testng.SuiteRunner.run(SuiteRunner.java:336)
at org.testng.SuiteRunnerWorker.runSuite(SuiteRunnerWorker.java:52)
at org.testng.SuiteRunnerWorker.run(SuiteRunnerWorker.java:95)
at org.testng.TestNG.runSuitesSequentially(TestNG.java:1280)
at org.testng.TestNG.runSuitesLocally(TestNG.java:1200)
at org.testng.TestNG.runSuites(TestNG.java:1114)
at org.testng.TestNG.run(TestNG.java:1082)
at org.testng.remote.AbstractRemoteTestNG.run(AbstractRemoteTestNG.java:115)
at org.testng.remote.RemoteTestNG.initAndRun(RemoteTestNG.java:251)
at org.testng.remote.RemoteTestNG.main(RemoteTestNG.java:77)
]]>
            </full-stacktrace>
          </exception> <!-- java.lang.AssertionError -->
          <reporter-output>
          </reporter-output>
        </test-method> <!-- loginValidationCorrectCredentials -->
        <test-method is-config="true" signature="tearDown()[pri:0, instance:com.TestNG.Oct_29_Day18_Retry_Failed_TestCases.LoginTest@5a45133e]" started-at="2023-10-29T14:16:24 EDT" name="tearDown" finished-at="2023-10-29T14:16:24 EDT" duration-ms="135" status="PASS">
          <reporter-output>
          </reporter-output>
        </test-method> <!-- tearDown -->
        <test-method retried="true" signature="loginValidationCorrectCredentials()[pri:0, instance:com.TestNG.Oct_29_Day18_Retry_Failed_TestCases.LoginTest@5a45133e]" started-at="2023-10-29T14:16:24 EDT" name="loginValidationCorrectCredentials" finished-at="2023-10-29T14:16:31 EDT" duration-ms="6564" status="SKIP">
          <exception class="java.lang.AssertionError">
            <message>
              <![CDATA[Deliberately failing to show students how to retry failed test cases in TestNG]]>
            </message>
            <full-stacktrace>
              <![CDATA[java.lang.AssertionError: Deliberately failing to show students how to retry failed test cases in TestNG
at org.testng.Assert.fail(Assert.java:111)
at com.TestNG.Oct_29_Day18_Retry_Failed_TestCases.LoginTest.loginValidationCorrectCredentials(LoginTest.java:26)
at java.base/jdk.internal.reflect.NativeMethodAccessorImpl.invoke0(Native Method)
at java.base/jdk.internal.reflect.NativeMethodAccessorImpl.invoke(NativeMethodAccessorImpl.java:77)
at java.base/jdk.internal.reflect.DelegatingMethodAccessorImpl.invoke(DelegatingMethodAccessorImpl.java:43)
at java.base/java.lang.reflect.Method.invoke(Method.java:568)
at org.testng.internal.invokers.MethodInvocationHelper.invokeMethod(MethodInvocationHelper.java:139)
at org.testng.internal.invokers.TestInvoker.invokeMethod(TestInvoker.java:664)
at org.testng.internal.invokers.TestInvoker.retryFailed(TestInvoker.java:248)
at org.testng.internal.invokers.MethodRunner.runInSequence(MethodRunner.java:62)
at org.testng.internal.invokers.TestInvoker$MethodInvocationAgent.invoke(TestInvoker.java:957)
at org.testng.internal.invokers.TestInvoker.invokeTestMethods(TestInvoker.java:200)
at org.testng.internal.invokers.TestMethodWorker.invokeTestMethods(TestMethodWorker.java:148)
at org.testng.internal.invokers.TestMethodWorker.run(TestMethodWorker.java:128)
at java.base/java.util.ArrayList.forEach(ArrayList.java:1511)
at org.testng.TestRunner.privateRun(TestRunner.java:848)
at org.testng.TestRunner.run(TestRunner.java:621)
at org.testng.SuiteRunner.runTest(SuiteRunner.java:443)
at org.testng.SuiteRunner.runSequentially(SuiteRunner.java:437)
at org.testng.SuiteRunner.privateRun(SuiteRunner.java:397)
at org.testng.SuiteRunner.run(SuiteRunner.java:336)
at org.testng.SuiteRunnerWorker.runSuite(SuiteRunnerWorker.java:52)
at org.testng.SuiteRunnerWorker.run(SuiteRunnerWorker.java:95)
at org.testng.TestNG.runSuitesSequentially(TestNG.java:1280)
at org.testng.TestNG.runSuitesLocally(TestNG.java:1200)
at org.testng.TestNG.runSuites(TestNG.java:1114)
at org.testng.TestNG.run(TestNG.java:1082)
at org.testng.remote.AbstractRemoteTestNG.run(AbstractRemoteTestNG.java:115)
at org.testng.remote.RemoteTestNG.initAndRun(RemoteTestNG.java:251)
at org.testng.remote.RemoteTestNG.main(RemoteTestNG.java:77)
]]>
            </full-stacktrace>
          </exception> <!-- java.lang.AssertionError -->
          <reporter-output>
          </reporter-output>
        </test-method> <!-- loginValidationCorrectCredentials -->
        <test-method is-config="true" signature="tearDown()[pri:0, instance:com.TestNG.Oct_29_Day18_Retry_Failed_TestCases.LoginTest@5a45133e]" started-at="2023-10-29T14:16:31 EDT" name="tearDown" finished-at="2023-10-29T14:16:31 EDT" duration-ms="130" status="PASS">
          <reporter-output>
          </reporter-output>
        </test-method> <!-- tearDown -->
        <test-method retried="true" signature="loginValidationCorrectCredentials()[pri:0, instance:com.TestNG.Oct_29_Day18_Retry_Failed_TestCases.LoginTest@5a45133e]" started-at="2023-10-29T14:16:31 EDT" name="loginValidationCorrectCredentials" finished-at="2023-10-29T14:16:37 EDT" duration-ms="6375" status="SKIP">
          <exception class="java.lang.AssertionError">
            <message>
              <![CDATA[Deliberately failing to show students how to retry failed test cases in TestNG]]>
            </message>
            <full-stacktrace>
              <![CDATA[java.lang.AssertionError: Deliberately failing to show students how to retry failed test cases in TestNG
at org.testng.Assert.fail(Assert.java:111)
at com.TestNG.Oct_29_Day18_Retry_Failed_TestCases.LoginTest.loginValidationCorrectCredentials(LoginTest.java:26)
at java.base/jdk.internal.reflect.NativeMethodAccessorImpl.invoke0(Native Method)
at java.base/jdk.internal.reflect.NativeMethodAccessorImpl.invoke(NativeMethodAccessorImpl.java:77)
at java.base/jdk.internal.reflect.DelegatingMethodAccessorImpl.invoke(DelegatingMethodAccessorImpl.java:43)
at java.base/java.lang.reflect.Method.invoke(Method.java:568)
at org.testng.internal.invokers.MethodInvocationHelper.invokeMethod(MethodInvocationHelper.java:139)
at org.testng.internal.invokers.TestInvoker.invokeMethod(TestInvoker.java:664)
at org.testng.internal.invokers.TestInvoker.retryFailed(TestInvoker.java:248)
at org.testng.internal.invokers.MethodRunner.runInSequence(MethodRunner.java:62)
at org.testng.internal.invokers.TestInvoker$MethodInvocationAgent.invoke(TestInvoker.java:957)
at org.testng.internal.invokers.TestInvoker.invokeTestMethods(TestInvoker.java:200)
at org.testng.internal.invokers.TestMethodWorker.invokeTestMethods(TestMethodWorker.java:148)
at org.testng.internal.invokers.TestMethodWorker.run(TestMethodWorker.java:128)
at java.base/java.util.ArrayList.forEach(ArrayList.java:1511)
at org.testng.TestRunner.privateRun(TestRunner.java:848)
at org.testng.TestRunner.run(TestRunner.java:621)
at org.testng.SuiteRunner.runTest(SuiteRunner.java:443)
at org.testng.SuiteRunner.runSequentially(SuiteRunner.java:437)
at org.testng.SuiteRunner.privateRun(SuiteRunner.java:397)
at org.testng.SuiteRunner.run(SuiteRunner.java:336)
at org.testng.SuiteRunnerWorker.runSuite(SuiteRunnerWorker.java:52)
at org.testng.SuiteRunnerWorker.run(SuiteRunnerWorker.java:95)
at org.testng.TestNG.runSuitesSequentially(TestNG.java:1280)
at org.testng.TestNG.runSuitesLocally(TestNG.java:1200)
at org.testng.TestNG.runSuites(TestNG.java:1114)
at org.testng.TestNG.run(TestNG.java:1082)
at org.testng.remote.AbstractRemoteTestNG.run(AbstractRemoteTestNG.java:115)
at org.testng.remote.RemoteTestNG.initAndRun(RemoteTestNG.java:251)
at org.testng.remote.RemoteTestNG.main(RemoteTestNG.java:77)
]]>
            </full-stacktrace>
          </exception> <!-- java.lang.AssertionError -->
          <reporter-output>
          </reporter-output>
        </test-method> <!-- loginValidationCorrectCredentials -->
        <test-method is-config="true" signature="tearDown()[pri:0, instance:com.TestNG.Oct_29_Day18_Retry_Failed_TestCases.LoginTest@5a45133e]" started-at="2023-10-29T14:16:37 EDT" name="tearDown" finished-at="2023-10-29T14:16:38 EDT" duration-ms="185" status="PASS">
          <reporter-output>
          </reporter-output>
        </test-method> <!-- tearDown -->
        <test-method retried="true" signature="loginValidationCorrectCredentials()[pri:0, instance:com.TestNG.Oct_29_Day18_Retry_Failed_TestCases.LoginTest@5a45133e]" started-at="2023-10-29T14:16:38 EDT" name="loginValidationCorrectCredentials" finished-at="2023-10-29T14:16:44 EDT" duration-ms="6726" status="SKIP">
          <exception class="java.lang.AssertionError">
            <message>
              <![CDATA[Deliberately failing to show students how to retry failed test cases in TestNG]]>
            </message>
            <full-stacktrace>
              <![CDATA[java.lang.AssertionError: Deliberately failing to show students how to retry failed test cases in TestNG
at org.testng.Assert.fail(Assert.java:111)
at com.TestNG.Oct_29_Day18_Retry_Failed_TestCases.LoginTest.loginValidationCorrectCredentials(LoginTest.java:26)
at java.base/jdk.internal.reflect.NativeMethodAccessorImpl.invoke0(Native Method)
at java.base/jdk.internal.reflect.NativeMethodAccessorImpl.invoke(NativeMethodAccessorImpl.java:77)
at java.base/jdk.internal.reflect.DelegatingMethodAccessorImpl.invoke(DelegatingMethodAccessorImpl.java:43)
at java.base/java.lang.reflect.Method.invoke(Method.java:568)
at org.testng.internal.invokers.MethodInvocationHelper.invokeMethod(MethodInvocationHelper.java:139)
at org.testng.internal.invokers.TestInvoker.invokeMethod(TestInvoker.java:664)
at org.testng.internal.invokers.TestInvoker.retryFailed(TestInvoker.java:248)
at org.testng.internal.invokers.MethodRunner.runInSequence(MethodRunner.java:62)
at org.testng.internal.invokers.TestInvoker$MethodInvocationAgent.invoke(TestInvoker.java:957)
at org.testng.internal.invokers.TestInvoker.invokeTestMethods(TestInvoker.java:200)
at org.testng.internal.invokers.TestMethodWorker.invokeTestMethods(TestMethodWorker.java:148)
at org.testng.internal.invokers.TestMethodWorker.run(TestMethodWorker.java:128)
at java.base/java.util.ArrayList.forEach(ArrayList.java:1511)
at org.testng.TestRunner.privateRun(TestRunner.java:848)
at org.testng.TestRunner.run(TestRunner.java:621)
at org.testng.SuiteRunner.runTest(SuiteRunner.java:443)
at org.testng.SuiteRunner.runSequentially(SuiteRunner.java:437)
at org.testng.SuiteRunner.privateRun(SuiteRunner.java:397)
at org.testng.SuiteRunner.run(SuiteRunner.java:336)
at org.testng.SuiteRunnerWorker.runSuite(SuiteRunnerWorker.java:52)
at org.testng.SuiteRunnerWorker.run(SuiteRunnerWorker.java:95)
at org.testng.TestNG.runSuitesSequentially(TestNG.java:1280)
at org.testng.TestNG.runSuitesLocally(TestNG.java:1200)
at org.testng.TestNG.runSuites(TestNG.java:1114)
at org.testng.TestNG.run(TestNG.java:1082)
at org.testng.remote.AbstractRemoteTestNG.run(AbstractRemoteTestNG.java:115)
at org.testng.remote.RemoteTestNG.initAndRun(RemoteTestNG.java:251)
at org.testng.remote.RemoteTestNG.main(RemoteTestNG.java:77)
]]>
            </full-stacktrace>
          </exception> <!-- java.lang.AssertionError -->
          <reporter-output>
          </reporter-output>
        </test-method> <!-- loginValidationCorrectCredentials -->
        <test-method is-config="true" signature="tearDown()[pri:0, instance:com.TestNG.Oct_29_Day18_Retry_Failed_TestCases.LoginTest@5a45133e]" started-at="2023-10-29T14:16:44 EDT" name="tearDown" finished-at="2023-10-29T14:16:45 EDT" duration-ms="138" status="PASS">
          <reporter-output>
          </reporter-output>
        </test-method> <!-- tearDown -->
        <test-method signature="loginValidationCorrectCredentials()[pri:0, instance:com.TestNG.Oct_29_Day18_Retry_Failed_TestCases.LoginTest@5a45133e]" started-at="2023-10-29T14:16:45 EDT" name="loginValidationCorrectCredentials" finished-at="2023-10-29T14:16:51 EDT" duration-ms="6418" status="FAIL">
          <exception class="java.lang.AssertionError">
            <message>
              <![CDATA[Deliberately failing to show students how to retry failed test cases in TestNG]]>
            </message>
            <full-stacktrace>
              <![CDATA[java.lang.AssertionError: Deliberately failing to show students how to retry failed test cases in TestNG
at org.testng.Assert.fail(Assert.java:111)
at com.TestNG.Oct_29_Day18_Retry_Failed_TestCases.LoginTest.loginValidationCorrectCredentials(LoginTest.java:26)
at java.base/jdk.internal.reflect.NativeMethodAccessorImpl.invoke0(Native Method)
at java.base/jdk.internal.reflect.NativeMethodAccessorImpl.invoke(NativeMethodAccessorImpl.java:77)
at java.base/jdk.internal.reflect.DelegatingMethodAccessorImpl.invoke(DelegatingMethodAccessorImpl.java:43)
at java.base/java.lang.reflect.Method.invoke(Method.java:568)
at org.testng.internal.invokers.MethodInvocationHelper.invokeMethod(MethodInvocationHelper.java:139)
at org.testng.internal.invokers.TestInvoker.invokeMethod(TestInvoker.java:664)
at org.testng.internal.invokers.TestInvoker.retryFailed(TestInvoker.java:248)
at org.testng.internal.invokers.MethodRunner.runInSequence(MethodRunner.java:62)
at org.testng.internal.invokers.TestInvoker$MethodInvocationAgent.invoke(TestInvoker.java:957)
at org.testng.internal.invokers.TestInvoker.invokeTestMethods(TestInvoker.java:200)
at org.testng.internal.invokers.TestMethodWorker.invokeTestMethods(TestMethodWorker.java:148)
at org.testng.internal.invokers.TestMethodWorker.run(TestMethodWorker.java:128)
at java.base/java.util.ArrayList.forEach(ArrayList.java:1511)
at org.testng.TestRunner.privateRun(TestRunner.java:848)
at org.testng.TestRunner.run(TestRunner.java:621)
at org.testng.SuiteRunner.runTest(SuiteRunner.java:443)
at org.testng.SuiteRunner.runSequentially(SuiteRunner.java:437)
at org.testng.SuiteRunner.privateRun(SuiteRunner.java:397)
at org.testng.SuiteRunner.run(SuiteRunner.java:336)
at org.testng.SuiteRunnerWorker.runSuite(SuiteRunnerWorker.java:52)
at org.testng.SuiteRunnerWorker.run(SuiteRunnerWorker.java:95)
at org.testng.TestNG.runSuitesSequentially(TestNG.java:1280)
at org.testng.TestNG.runSuitesLocally(TestNG.java:1200)
at org.testng.TestNG.runSuites(TestNG.java:1114)
at org.testng.TestNG.run(TestNG.java:1082)
at org.testng.remote.AbstractRemoteTestNG.run(AbstractRemoteTestNG.java:115)
at org.testng.remote.RemoteTestNG.initAndRun(RemoteTestNG.java:251)
at org.testng.remote.RemoteTestNG.main(RemoteTestNG.java:77)
]]>
            </full-stacktrace>
          </exception> <!-- java.lang.AssertionError -->
          <reporter-output>
          </reporter-output>
        </test-method> <!-- loginValidationCorrectCredentials -->
        <test-method is-config="true" signature="tearDown()[pri:0, instance:com.TestNG.Oct_29_Day18_Retry_Failed_TestCases.LoginTest@5a45133e]" started-at="2023-10-29T14:16:51 EDT" name="tearDown" finished-at="2023-10-29T14:16:51 EDT" duration-ms="151" status="PASS">
          <reporter-output>
          </reporter-output>
        </test-method> <!-- tearDown -->
      </class> <!-- com.TestNG.Oct_29_Day18_Retry_Failed_TestCases.LoginTest -->
    </test> <!-- Default test -->
  </suite> <!-- Default suite -->
</testng-results>
