<?xml version="1.0" encoding="UTF-8"?>
<!-- Generated by org.testng.reporters.JUnitReportReporter -->
<testsuite hostname="SarthakDell" failures="1" tests="6" name="com.TestNG.Oct_29_Day18_Retry_Failed_TestCases.LoginTest" time="41.729" errors="0" timestamp="2023-10-29T14:16:51 EDT" skipped="5">
  <testcase classname="com.TestNG.Oct_29_Day18_Retry_Failed_TestCases.LoginTest" name="loginValidationCorrectCredentials" time="8.148">
    <skipped/>
  </testcase> <!-- loginValidationCorrectCredentials -->
  <testcase classname="com.TestNG.Oct_29_Day18_Retry_Failed_TestCases.LoginTest" name="loginValidationCorrectCredentials" time="6.505">
    <skipped/>
  </testcase> <!-- loginValidationCorrectCredentials -->
  <testcase classname="com.TestNG.Oct_29_Day18_Retry_Failed_TestCases.LoginTest" name="loginValidationCorrectCredentials" time="6.699">
    <skipped/>
  </testcase> <!-- loginValidationCorrectCredentials -->
  <testcase classname="com.TestNG.Oct_29_Day18_Retry_Failed_TestCases.LoginTest" name="loginValidationCorrectCredentials" time="6.603">
    <failure message="Deliberately failing to show students how to retry failed test cases in TestNG" type="java.lang.AssertionError">
      <![CDATA[java.lang.AssertionError: Deliberately failing to show students how to retry failed test cases in TestNG
at org.testng.Assert.fail(Assert.java:111)
at com.TestNG.Oct_29_Day18_Retry_Failed_TestCases.LoginTest.loginValidationCorrectCredentials(LoginTest.java:26)
at java.base/jdk.internal.reflect.NativeMethodAccessorImpl.invoke0(Native Method)
at java.base/jdk.internal.reflect.NativeMethodAccessorImpl.invoke(NativeMethodAccessorImpl.java:77)
at java.base/jdk.internal.reflect.DelegatingMethodAccessorImpl.invoke(DelegatingMethodAccessorImpl.java:43)
at java.base/java.lang.reflect.Method.invoke(Method.java:568)
at org.testng.internal.invokers.MethodInvocationHelper.invokeMethod(MethodInvocationHelper.java:139)
at org.testng.internal.invokers.TestInvoker.invokeMethod(TestInvoker.java:664)
at org.testng.internal.invokers.TestInvoker.retryFailed(TestInvoker.java:248)
at org.testng.internal.invokers.MethodRunner.runInSequence(MethodRunner.java:62)
at org.testng.internal.invokers.TestInvoker$MethodInvocationAgent.invoke(TestInvoker.java:957)
at org.testng.internal.invokers.TestInvoker.invokeTestMethods(TestInvoker.java:200)
at org.testng.internal.invokers.TestMethodWorker.invokeTestMethods(TestMethodWorker.java:148)
at org.testng.internal.invokers.TestMethodWorker.run(TestMethodWorker.java:128)
at java.base/java.util.ArrayList.forEach(ArrayList.java:1511)
at org.testng.TestRunner.privateRun(TestRunner.java:848)
at org.testng.TestRunner.run(TestRunner.java:621)
at org.testng.SuiteRunner.runTest(SuiteRunner.java:443)
at org.testng.SuiteRunner.runSequentially(SuiteRunner.java:437)
at org.testng.SuiteRunner.privateRun(SuiteRunner.java:397)
at org.testng.SuiteRunner.run(SuiteRunner.java:336)
at org.testng.SuiteRunnerWorker.runSuite(SuiteRunnerWorker.java:52)
at org.testng.SuiteRunnerWorker.run(SuiteRunnerWorker.java:95)
at org.testng.TestNG.runSuitesSequentially(TestNG.java:1280)
at org.testng.TestNG.runSuitesLocally(TestNG.java:1200)
at org.testng.TestNG.runSuites(TestNG.java:1114)
at org.testng.TestNG.run(TestNG.java:1082)
at org.testng.remote.AbstractRemoteTestNG.run(AbstractRemoteTestNG.java:115)
at org.testng.remote.RemoteTestNG.initAndRun(RemoteTestNG.java:251)
at org.testng.remote.RemoteTestNG.main(RemoteTestNG.java:77)
]]>
    </failure>
  </testcase> <!-- loginValidationCorrectCredentials -->
  <testcase classname="com.TestNG.Oct_29_Day18_Retry_Failed_TestCases.LoginTest" name="loginValidationCorrectCredentials" time="6.907">
    <skipped/>
  </testcase> <!-- loginValidationCorrectCredentials -->
  <testcase classname="com.TestNG.Oct_29_Day18_Retry_Failed_TestCases.LoginTest" name="loginValidationCorrectCredentials" time="6.867">
    <skipped/>
  </testcase> <!-- loginValidationCorrectCredentials -->
</testsuite> <!-- com.TestNG.Oct_29_Day18_Retry_Failed_TestCases.LoginTest -->
